// try catch in aysnc-await

try {
    let x = 2;
    const y = 4;
    y = 8;
} catch (err) {
    console.log("something went wrong in try section");
}